# 天翼云盘签到记录

[![签到状态](https://github.com/xdrive5/cloud9/actions/workflows/main.yml/badge.svg)](https://github.com/xdrive5/cloud9/actions/workflows/main.yml) [![项目主页](https://img.shields.io/badge/GitHub-项目主页-blue?logo=github)](https://github.com/xdrive5/cloud9)

**最后更新:** 2025-10-19 17:35:33 CST

📋 [查看最新运行](https://github.com/xdrive5/cloud9/actions/runs/18628578548) ⚙️ [手动触发签到](https://github.com/xdrive5/cloud9/actions/workflows/main.yml)

## 执行概览
- **启动时间**: 2025-10-19 17:35:33
- **账户数量**: 2 个

## 账户1
登录过程出错: HTTPSConnectionPool(host='open.e.189.cn', port=443): Max retries exceeded with url: /api/logbox/oauth2/autoLogin.do?appId=cloud&version=v1.1&clientType=20010&format=redirect&paras=A9C0B7A709951CDA0872192583162B5716A986D8B72BC13DE456BB167B930D2FDF3B7B1C9862860310F86478A46797CA91EF6BDFC3CD22081394A83D6DA3DCC23340068C84EDE3D829B88F90A542C808567D15AF37B23DC86F115D499663F8975BF8F1C4694C668188813EBCC6E1E8C5B40792F03983C83A4CE71AB6784C39DAA2E2C5A4D31986032ECC7191A6A4658C514CA9AEAE52710299896B311D5DBBC80C7DC24E39D7CCC8E645AB6C7651E7525D0BBEC93BB484B3C4BDC59E322C92A68F381F8D4F11E210B2B3362AEA7C7939DDDA9A00D5992B4C947289B90C0E0076CE1E193E785B2AB39E63973110C078AF6C2ADDCE07812D8E742942D0D8EBC22C6428A3D2A3B7111FE0480A9EDB1426E7CE226676CC944999D1E66C0EB223157AB13C90CE269D207AABDBB140BF43F5DB95F2EDC2222FB155CF00220EE5A6EC70354575989D6325870861E05FBA6BAB51A4985B164B4BE399E0D1D1030B818C08956B0C277FC2528BD1454EC4FD33D78ABB1C47E1DB9A6E331266E0B9DF11FBF81C0B6836796C8CFFE40F1B984940FEF14266F32EE7B97C5E9BDA0B2B58A77C8F05B1EE1157F8C5582044D97626B4C6A354830E2329F47CB6CD1F29096621B3F7216F85E248D17F172E91147A473AD92CC160BDB5E7B4F9E4B7C02E3B09B1BEACD1CB960979B02C51352D7103D5E260D89529070D58D3D805786DF5637721970981FE15DE8440DED84D15B0E43D13DF35A84B7F4459269948&sign=8FE87A96F9F4C659EA06F462CF723243378AC93D (Caused by NewConnectionError('<urllib3.connection.HTTPSConnection object at 0x7f0b1fb34410>: Failed to establish a new connection: [Errno 101] Network is unreachable'))
- **登录状态**: 登录失败
- **签到结果**: 

## 账户2
登录过程出错: HTTPSConnectionPool(host='open.e.189.cn', port=443): Max retries exceeded with url: /api/logbox/oauth2/autoLogin.do?appId=cloud&version=v1.1&clientType=20010&format=redirect&paras=8A01D227C830CAD8AEF3ECB77148E3CA8B0F836CC2DC441F2CEBA8DA6B0CABF7C7558D36609E295A329CF67456EF1CB60ED89CD462E956B2EC5B9F7B76DB307A2C548EE80C577299235C44285EC94EB2CE55D268B7E71817BF9605CD23634E824FA60BE6E5FA613F400BE1A371402A5423A98C49657C9EB989C19BF11A865274DBA7FDC302AF2F659680DC0273F05DE1C35A6871FAA4C91767B22FAF6B4E6ED130D23AE4FE834850273BD174F2095D244AC321018CAB8D227A14C64008E80A1E0EC7B6374CD5D5F4D23CA35CBC91D77E10A32D07A5689F94025F8F59B036DE863693731339258D2ABE112A367EDF992E2A2819CDECC9810A741C61E9F88646A5EFB119EF6AABF04851B85A715655E90CA3717D4FAC7DF06DE7BA24649B6815E0C94238B5DBFE1A852AC7FFAB5BF0A56D0D4F6871F241FD14D1F877EE951378D2FAA9AA625EA93038EFBCD6A09EBB03D74177CF58358E4ACF6BFBDFD2FF0CA7D3F0E432B61BA97B557FBE29ED68E6692FB852E68739C555FFB2C05B19AE943787EE60157C7851CB8DBFAF605A92EF8A758DACDBEFBCECD39EE01B39BEBC7210C8039A60FDB84E8C241961F88B338A247CB0E60E03A44DFAE7763AF3BC93CB776931851540F09144A572AEC57398A627ADFD98B5AE8C1A750853E0BA58525EA300DE4AA897E7D950836A2BA3C1D22B54F21898AC7093752C83D8AF7B4651FE5E090AE1FDBF09E7B8E832800C4493D8D07D6E148FACA3CA8FFA&sign=8400EDABA013AF15EC1258D373378E5A026FD961 (Caused by NewConnectionError('<urllib3.connection.HTTPSConnection object at 0x7f0b1fb37ad0>: Failed to establish a new connection: [Errno 101] Network is unreachable'))
- **登录状态**: 登录失败
- **签到结果**: 

---
## 执行统计
- **结束时间**: 2025-10-19 17:44:38
- **运行时长**: 545.04 秒

✅ **所有账户处理完成！**
