# 天翼云盘签到记录

[![签到状态](https://github.com/xdrive5/cloud9/actions/workflows/main.yml/badge.svg)](https://github.com/xdrive5/cloud9/actions/workflows/main.yml) [![项目主页](https://img.shields.io/badge/GitHub-项目主页-blue?logo=github)](https://github.com/xdrive5/cloud9)

**最后更新:** 2025-09-15 03:43:22 CST

## 快速导航

- 🔄 [查看Action运行记录](https://github.com/xdrive5/cloud9/actions)
- 📋 [查看最新运行](https://github.com/xdrive5/cloud9/actions/runs/17715809343)
- 🏠 [返回项目主页](https://github.com/xdrive5/cloud9)
- ⚙️ [手动触发签到](https://github.com/xdrive5/cloud9/actions/workflows/main.yml)

## 签到详情

# 天翼云盘自动签到抽奖程序

## 执行概览
- **启动时间**: 2025-09-15 03:43:23
- **账户数量**: 2 个

## 账户1
登录过程出错: HTTPSConnectionPool(host='open.e.189.cn', port=443): Max retries exceeded with url: /api/logbox/oauth2/autoLogin.do?appId=cloud&version=v1.1&clientType=20010&format=redirect&paras=482F8010D453B02B186B36B7B90E8707263C094BECE12ABA958C6670D1D3E408CFFD1170100E5BB53051F5867464EA0B49E89ED4BF59F60D712158B182AB536EE99A09EA405B4B911269F08A25BB8BA7FEF4FAE5F5BBE74365E7402853A379398BA8D506CB0B219399010DDAF2DED6B1F962897AE1D8589AF8F89FDA4D32469E3AFA9C5946784169E8404901520F50306E2C41318371194D62C0BCECF6788F18A944D2342A49A218E456CA125E52775AE45D9D233D34D8576E786DE5FEDFDFE25C7DB07C3E0787E30F58D0138E7F62D3A4F3B65DAF80BD4EEF6D53D2AD65E961F585BE8B9BFAC24423501D340AD0037356539F263928A0C45BA76970C0EDCA5B830E482673265D3F595F1425B68FE7B56E75AB3AC54DACDAC6ECB1BD9B926322CFD162109E407300D8CCF2DBBF864014E150D71DCCEF19D96800EB9368489A852286866D0B0F7AE67C8E36D0785D57DA67F7AF78BB0B0714A8AB4C4A8E3B077834E3129CD4F5FDDC80171717287F0E45CB22796B9A13891FCA8D76BF874840526BB21B3F6E7F8EDDB05D866BB1910757BFD618D05706590671A51D1E7D80BA3BA3D095D8B2EEF1424FE495E5E1E88C3073F839202738AEC1C709170680E762C6F37BB6DA2E7756F27A455F248CCB4C4AF05FED7C778BAA52CFC25E22DA5328AEB70E3F3A494274EFA7BB327FDA498EBE1570270B69B091B32A1B72639D71CF2A5500DCE233E8D68A2FD067FD71C45A6F6720B9BF3692CC77&sign=2174637E5F01548E02299DF3205A115858A53464 (Caused by NewConnectionError('<urllib3.connection.HTTPSConnection object at 0x7f1ae4b98510>: Failed to establish a new connection: [Errno 101] Network is unreachable'))
### 执行结果
- **登录状态**: 登录失败
- **签到结果**: 

## 账户2
登录过程出错: HTTPSConnectionPool(host='open.e.189.cn', port=443): Max retries exceeded with url: /api/logbox/oauth2/autoLogin.do?appId=cloud&version=v1.1&clientType=20010&format=redirect&paras=BBFBCD42B322AE1971E6442EF26D814C3D33F58611856F6F3102DF640F95D88DE835B05D29D89CFF09532818CADB30ABFA8D4374A0280C368E428C9820AAEB8245E04A3B2EB2C023D79FD20F0ACA455E95D1F56C07EB26ECBAA0F0AF661A063E649304C12DAD6ECAFCFF772914D5953DD1A67C7A30918447C220A5F6E24FA6F2D7226F43E203AE82BFD352ECDC77D55D6202B6A966500215F3BB37B026EA31F0888D86C49FB2965101CA0C8FD63A19F2297BC8224EF08AE7D07FF0906B1E2E0934B73C068EF1F2DF5FDBC6A48CFFC90E3BAD7F920C780D721C59836939AD12D82544667DA11FDC6B4763E24AD492230669586270B3AF9D5F71C519D42B2CCA80BEB7E9467AA401BAADD1F4B604AE5F2957980B5E5C059821EAAFBE9F47A3D9AF4F90C2ECD9A887B09E2A50AF57B49CD50FAF415BC5D9286A0A477229F5A34ECCA4CF663DC0CBDD0D0F3D4F0C5E1FD82D4005170A316AA82F76B025903383AD32073D68237286A02AC6FDC69D3293F253E38049CF84DE9285F8F1739765671CD9B239BD01D2ED5AA2CBE822697FEE7605540A9721A537A7EBAC28C10DCD16CC0FB03790ECF0E6D84CB33C6392B51452D92332AFA37805DB789A259C42C75647B40E447406706D5C732E30ED72B682568E6DC6B1084E01541A1E1EE61D8190D23FE1BA29A645066901F29C599014A39D2B10C8FE1A73FFC40E00D37167B95E3604EE43CB26299FDB37576057AA0081B93DF51FFBF6A4BE946F&sign=BFE692AE80787FC8DFED117501F4C516C7D155F3 (Caused by NewConnectionError('<urllib3.connection.HTTPSConnection object at 0x7f1ae4b9bc50>: Failed to establish a new connection: [Errno 101] Network is unreachable'))
### 执行结果
- **登录状态**: 登录失败
- **签到结果**: 

---
## 执行统计
- **结束时间**: 2025-09-15 03:52:26
- **运行时长**: 543.85 秒

✅ **所有账户处理完成！**
