# 天翼云盘签到记录

[![签到状态](https://github.com/xdrive5/cloud9/actions/workflows/main.yml/badge.svg)](https://github.com/xdrive5/cloud9/actions/workflows/main.yml) [![项目主页](https://img.shields.io/badge/GitHub-项目主页-blue?logo=github)](https://github.com/xdrive5/cloud9)

**最后更新:** 2025-10-02 05:29:12 CST

📋 [查看最新运行](https://github.com/xdrive5/cloud9/actions/runs/18176189230) ⚙️ [手动触发签到](https://github.com/xdrive5/cloud9/actions/workflows/main.yml)

## 执行概览
- **启动时间**: 2025-10-02 05:29:12
- **账户数量**: 2 个

## 账户1
登录过程出错: HTTPSConnectionPool(host='open.e.189.cn', port=443): Max retries exceeded with url: /api/logbox/oauth2/autoLogin.do?appId=cloud&version=v1.1&clientType=20010&format=redirect&paras=B1B4B437ED117324940D4288843281B5449A36895CAB30A3D783F22FD554061231585198F9497965B31D992EABB6C55E16C8BDF11596D083E5EA0E6FF25218929807CE4F813D4FFA97C37F669F14E5CACE4DF5CE567FCF17A96FD92448E0420290D8EB536D1BDE9738A4186582A203A63A3DCAC518759B6EB13031853E820D95F60416D6D94B48074CD20045286D1F6097845B2649D31CB380E33F5DD8F84BDEC92D8045EDBBF82B8476F2AE6A40C151E253EFD306B4C5E77CC750F12ED7C364B4472BCF7915A59C710F236C1BC87D73DF9D2EE62D985411D9949E78719E789ACC22CF98F22FD4653F365E5A676736DE416BF448869239F7B93620CE15B03013CB85344667E009A293D71B255184C2C5694A791D0F79698F137081673850F009981BA5828DCDE7B73001CB6F7C51C1C8B26074F616CC50184E9507CFCE1036C16F0C2AB43689002DFDE267CA84C8AEDA83458840EF55B2606D79F9C95AEF971173F05A11671CAF5F2ECB2B74BC60D6CB5142D7A8F9B3036865B0CE35CA2E0EFF8CC025B7BA19A065ACA159C6C5C14E1EBD5A7D857BE48A8029755AAF1C9FF618DFCE84432DB35D43F3B28AD739AA924E6257493B87CF7FB3BD33C9779F9B8725FB6A70AEF109B038BAB0422CE48D31A35AE8CF9DE93D0448344E4B9B1F0B7CEEE2887E6DC358CF7316AEADE5998CE95AD9F339CC17C79B6F0E9B50E672C583894E7131932315B0CDED0C8E8F8807005DE0C3DCF5E4A9D169&sign=70A57AB8AB21805847E3050B7B9D239EDF22FD62 (Caused by NewConnectionError('<urllib3.connection.HTTPSConnection object at 0x7efc8188cd10>: Failed to establish a new connection: [Errno 101] Network is unreachable'))
- **登录状态**: 登录失败
- **签到结果**: 

## 账户2
登录过程出错: HTTPSConnectionPool(host='open.e.189.cn', port=443): Max retries exceeded with url: /api/logbox/oauth2/autoLogin.do?appId=cloud&version=v1.1&clientType=20010&format=redirect&paras=B43A39502D9B27764B599970BC2FB2930C17882BEF85EC50114FDE078366AE9A976F299905BEC60CD5B80F094C318522DE32FFE635367AB4F6CEBB6E6FEFAA7B9DA5F2773F4E68889D1F736ADAFCBE660D766534038147F999771EEF8B78D8AF754A867B28CF22EBDFB1DB0A187655ACA397D68F0E3B484FFC6E4022EC1177C36CAB2F5C7D8CBDE0B5A8B9C00E620223DEFCE4B6BC226C74B37E91A380CEBF92E1AF0DDD4FBBF7CA898C7F27AA2F1A137000AE07C3654937F93B28FE8E7549B50BFA511B8DDB6B638D4712FDD61D780A69B2D1260112341224F85F70642B3FD9F3672CF551C34617C8776CF5B1D8EDA48845A1E8F440A291B20C681933719214730EA27A1AC87ACF0CBFBD10065EB3F20466E12D438644FB0E007CC3D09FC275FE7D226CEC494A5CFCD4FB89029A526620EE6793913851E476DC1550707070EFA1ACD2319DFDBA6B69F67C2B3D0DEB2B45A5F4186FC5E88D287D0496974CE823A4C61E7E4B256F94E34DA723CD4E09A580C9FB5865E5DC264091D89D6A9001AA7A231BE61602C4BD6B0C11F855BC4A7D102611A34DE1B392058C9FA033309E77316533BD14EE0725686D551C64E49A8452BD31C63BCE17F918888CAF83DE582575990721553A2439B83A05E04AB37EFE147146B06EF9984A01F4726D4459FF9A06E3667C5BC6D29A5D40EA6744F66891B2115DD33DA1E10DB84EABFC47B80D7CF636711A23C496D6D2A7873B15454EE985F37E3DD2F5BE18&sign=166F4E1014C1B0E57839EFFEDC2A1E30CFA65B81 (Caused by NewConnectionError('<urllib3.connection.HTTPSConnection object at 0x7efc818984d0>: Failed to establish a new connection: [Errno 101] Network is unreachable'))
- **登录状态**: 登录失败
- **签到结果**: 

---
## 执行统计
- **结束时间**: 2025-10-02 05:38:14
- **运行时长**: 542.14 秒

✅ **所有账户处理完成！**
