# 天翼云盘签到记录

[![签到状态](https://github.com/xdrive5/cloud9/actions/workflows/main.yml/badge.svg)](https://github.com/xdrive5/cloud9/actions/workflows/main.yml) [![项目主页](https://img.shields.io/badge/GitHub-项目主页-blue?logo=github)](https://github.com/xdrive5/cloud9)

**最后更新:** 2025-10-05 15:27:15 CST

📋 [查看最新运行](https://github.com/xdrive5/cloud9/actions/runs/18255685558) ⚙️ [手动触发签到](https://github.com/xdrive5/cloud9/actions/workflows/main.yml)

## 执行概览
- **启动时间**: 2025-10-05 15:27:15
- **账户数量**: 2 个

## 账户1
登录过程出错: HTTPSConnectionPool(host='open.e.189.cn', port=443): Max retries exceeded with url: /api/logbox/oauth2/autoLogin.do?appId=cloud&version=v1.1&clientType=20010&format=redirect&paras=5F356789C7648785045084D00F4474710365CEF7ECEB72F7B26456FDC8B74D9908381AD70AA06E70FACEB8970A4CDAF858AE9705B6B8E9D072D582EB35625AD0DDC55CCC1484E4746DBC5E16F7F7D564CA3EF6CAD2FB05C6A5F606CB573F062CFFB5C3AD9EAD839F54377D651D126BF212CA8F821664D1E1EDFA9F9BEDFD141D6A07F89894866F27B0360A429BBEAFD9C92D65CCF762C8E52E66D05D7CB7B18910B8D1AA03D676F43E394F503D916B1B258B9218A5A129242A6F9274177C7619CE99E4F02DC382CBE55A569594DF731EE88AE94973FCEAA98F5E0E5A6CEAF445310F003F0B09E6C4E4EDE859E50C2522BCCC87C83FD5DB53488D19C41A09454B6D2EFEDE2C4549BBB776D15D3B9005246DD0C00EDEA26A07D6BBE309C5CF80BFBF1B25C4D4751A0239B8918AB4B39A25E5BA2A3BF05E36CAA84DF44A1B0B7F185A215B74AD50102888FAB6FF524978A2C19EA5AEF326E81D687F6AF0992BCC4798471CDF208C84A2A5B6940A4C412F80AA8EC6DAF9FB94EB390BC7BBC3F2C65164940304F223133F2811CBFB795AC6FB73B6669097B6DA16E11BDB9AA980545F89EDD8FAF657610C8574F1B482E85B169004101AF64C2A94D647657FADBE3DCB7638E166A8A851093EE2B6999D23468F8250BE75B5E90695DC632667F549BAB0C58DC4FDEF0386005E0A61C30E3B474426754D21FED3A9C3C41C06F7024D3F1FD7549A9B86E6C7BF836E99F4E559AA595EB7E7F62ECC77DD&sign=E9947CF6FC9FE7258DDD262C027EB1631E4887E6 (Caused by NewConnectionError('<urllib3.connection.HTTPSConnection object at 0x7fef02198490>: Failed to establish a new connection: [Errno 101] Network is unreachable'))
- **登录状态**: 登录失败
- **签到结果**: 

## 账户2
登录过程出错: HTTPSConnectionPool(host='open.e.189.cn', port=443): Max retries exceeded with url: /api/logbox/oauth2/autoLogin.do?appId=cloud&version=v1.1&clientType=20010&format=redirect&paras=15B58023C765779A99D85368A72A69D29364A89424BA87789B74DE82EF22AAD733B6C71FCECC497B65C6364D6F6F528C24DC1CD4374CC45520507E847475B8E4944A9928AC9551DAB31F43C79D643D4C695B21D03F6FD6EA07B4CD8E6F0F73E673C23BC9C9CE80350EE19F2F047DD6220ACBA8A2A242CC66B1920A707B21C74492D657694112795E3BAAAB20E821701DE42057AC932389EC71A10ECD73AF5B095001E2E2F4ECBE851C1459E040442201EF938AA429230C117E29DE7CF85268FAB962D847D73D2914A1C4CF6844E8194E3DB7CE0365987EFE210C34F4CF5361DF0CCD842D6F3493553B7E0E0A6BB090BD7E66DD10BB5D359EAA8517DED64F094F43CBDE5D8BA937D02D708585F3253763C91AE4D48A8ED7E7291CAFBB9B0D9AAA61D0C49B4D19B247DCBBE94A2DE791DF20E8FC43AD8EDB13DD2C797C2A79382F68F6ADD6120F7B3136EAADECFEC1458688396777AAA1EEB51B636CCA034944422B2099876452F8B92699C79A880EE2E7018B8B52FC33D773007BD2D9B823712612D07936A363A3579D03CB8578EC6B5BDDF0B1E6866B6ECAF181DDCE1DC791E44BC547B0A0A557DAF33054180FF45ECCB25842302C19D27C3A7238266017993CB518EB5732346460388CDA2469E197123A1AE1ACA585F581B3B65E3B1A66FE6D3CCF89E10F37C68F6AF46C50E629ED097B0B11EA4E69E51D55298B61960BE597C4B6ACA9D1881F39634830112E64526C5586B6192970E914&sign=D849A7157B146356C397D0E4F99FF5F3A367CB81 (Caused by NewConnectionError('<urllib3.connection.HTTPSConnection object at 0x7fef0219bc10>: Failed to establish a new connection: [Errno 101] Network is unreachable'))
- **登录状态**: 登录失败
- **签到结果**: 

---
## 执行统计
- **结束时间**: 2025-10-05 15:36:23
- **运行时长**: 548.35 秒

✅ **所有账户处理完成！**
