# 天翼云盘签到记录

[![签到状态](https://github.com/xdrive5/cloud9/actions/workflows/main.yml/badge.svg)](https://github.com/xdrive5/cloud9/actions/workflows/main.yml) [![项目主页](https://img.shields.io/badge/GitHub-项目主页-blue?logo=github)](https://github.com/xdrive5/cloud9)

**最后更新:** 2025-10-31 17:40:02 CST

📋 [查看最新运行](https://github.com/xdrive5/cloud9/actions/runs/18968658783) ⚙️ [手动触发签到](https://github.com/xdrive5/cloud9/actions/workflows/main.yml)

## 执行概览
- **启动时间**: 2025-10-31 17:40:02
- **账户数量**: 2 个

## 账户1
登录过程出错: HTTPSConnectionPool(host='open.e.189.cn', port=443): Max retries exceeded with url: /api/logbox/oauth2/autoLogin.do?appId=cloud&version=v1.1&clientType=20010&format=redirect&paras=C45501FA9026CF97BCED18D48262A376D31A793B24ADBFECDEAD546CCD0875E2FD1C3A46A9D9CF748832A6A2A2431442540A50B24D286840C2871B94D1384E7691A123C4457F6F29E1B901FFCB3A8E1FE33317D230EF3CFB9CB48CC3B5A9145C16597D602C2B977090399A950CB82B126376C0BC53E1F1795D946F5134ADC1DC39FE1724C44D04BF3E1772D508A0AA5D912087FCD0F4EB3140C5D42024F1293CC41CCABE1DEE188F8D4859CDFAE8E9A0D567659536D89FE3AEA4BDC22D8AFC92AE2B7B33CECA50DB346663856AEF077055430C9C5AF7DF74EB278E6D65807432D75344239600DF4B17811552BDB306CDFB84510BD29BFE89BFA91A9018CDA6C0849FFA6DE89C85E6261CF97D47381BBD1D81D52FE91323D24B18DE354AD0C475BB2D355396719F8AC9CACE46D85D1A34133D326B3937C253C54CBCD2DD9BFA12496589978787CCCFB363CBC77950FAFFDCFD25FB3501107B2D918E55D951632D40B62F5CB2FCE54980556B39AEDA7AD2A0927E7318A3653332A11C06195C9DF38B0DA1B5BEC8206650782D30199DDCF38A7493CC0BB2A41ECC731392DDAD5E16880CF302D3B17B2FB39AC62940720A02036CE1D2219B88548AB8641ED728976CA140D58D70DF26FB851BE4382FA443B1EF00F76F1164ED83512B56952570967B721D5742237107FCEE2175E3E403A59724D3A5B877B5B0C74816B7C9E5A52A2ECEA3382D3CE68CE2E9E908AE4B192BF5D744C5F7839FA41C&sign=87B80AA6B4A0179D4372C91B4DF3972FEE7C6A3D (Caused by NewConnectionError('<urllib3.connection.HTTPSConnection object at 0x7f00bf610c10>: Failed to establish a new connection: [Errno 101] Network is unreachable'))
- **登录状态**: 登录失败
- **签到结果**: 

## 账户2
登录过程出错: HTTPSConnectionPool(host='open.e.189.cn', port=443): Max retries exceeded with url: /api/logbox/oauth2/autoLogin.do?appId=cloud&version=v1.1&clientType=20010&format=redirect&paras=E91C617BDDA63ED557C3A0B4ED42B8D501012F5C603E386C85F55EE28FC74FFEFE18B9E7088A38B756F81380D29876A8253BA199BCF4176F63E4A168BBBEBF49649A5FB74CCDDE47545C9871A3E1CC059D9CC88BFF2BB484B3F5E13D0277250C27421FBAB6DF9AE8C1ED8DA7D0FAA0E5F57E16558168CE2E4DA75A79FF22624BA194690C43897E17B0807A84DAC988ED96775B9CFAB49825F916427F408B479EE1541E7CE9608CEE5D0A24822FE3DD8C5D7521E96C8BF372132DCEE4E028223FFE7CDB2A04B6602EA4CB5E5901046DC0EF65DCFAA5EEFBD42FE673C6883F42915BBAF3D3F3E59D2D65CCC9E83C9321A35E06EDAE5611E3EE8DC60CB2F85FCABFD7EB2397387BF3BCC6230A6A5E4D19799E5ABF39D0120864DA173611D9AC30A8D91274F40F9C2F6609306196382A67AD312D80F87C394B823BDE911513902E05815F4C3F029E329E5657FF859CC9217716782591FE056C19720041B76A20E3FE9C1D84DB55C71E92AA6D7D708DA2D7EBA403EF0D2824F410CDAC6F2ED4FCDB2FBE96A756C9D2652F62EE54B6737666221C683AD812CA738C23022C4B0284D485334C110F88D014A2E644E0F76321B1B635D6B4D5BC16574082C265AD4DFD636C1786BAE8F2FCC7190BC146CA9763E972D40D3E8A105A48CCBB4C8E259ED078B6AA1C88E0A30CB440DE80FEE87D2DA02482336CCDCA899159D7BB0419190B03C74423408CC1E4FD25C6748B724B98E4BB0BA5829470F5BF34&sign=5B5D58F9591B9996532A52CE8B1BEC3EFE13B75E (Caused by NewConnectionError('<urllib3.connection.HTTPSConnection object at 0x7f00bf61c350>: Failed to establish a new connection: [Errno 101] Network is unreachable'))
- **登录状态**: 登录失败
- **签到结果**: 

---
## 执行统计
- **结束时间**: 2025-10-31 17:49:10
- **运行时长**: 547.71 秒

✅ **所有账户处理完成！**
