# 天翼云盘签到记录

[![签到状态](https://github.com/xdrive5/cloud9/actions/workflows/main.yml/badge.svg)](https://github.com/xdrive5/cloud9/actions/workflows/main.yml) [![项目主页](https://img.shields.io/badge/GitHub-项目主页-blue?logo=github)](https://github.com/xdrive5/cloud9)

**最后更新:** 2025-09-18 05:26:27 CST

## 快速导航

- 🔄 [查看Action运行记录](https://github.com/xdrive5/cloud9/actions)
- 📋 [查看最新运行](https://github.com/xdrive5/cloud9/actions/runs/17811127742)
- 🏠 [返回项目主页](https://github.com/xdrive5/cloud9)
- ⚙️ [手动触发签到](https://github.com/xdrive5/cloud9/actions/workflows/main.yml)

## 签到详情

# 天翼云盘自动签到抽奖程序

## 执行概览
- **启动时间**: 2025-09-18 05:26:27
- **账户数量**: 2 个

## 账户1
登录过程出错: HTTPSConnectionPool(host='open.e.189.cn', port=443): Max retries exceeded with url: /api/logbox/oauth2/autoLogin.do?appId=cloud&version=v1.1&clientType=20010&format=redirect&paras=EB4215A7D6D60D1D47FBA5607AD24D5AB517E5849929155204087C49FFB38F7F6A41BE14FCD1277B98E367BAA7B3AA044D47C5C1EB5AF9EDE360C679796DCF30BFC38614DB671D312ECE6232DA3473ED188CFBEB3A6A5338EF821014F189122E0E611014D9467D0969D83B5ADEB96035A154CA773CDD2D49DBE1B915A03FB74B5745877E97A8914E2280EB3D19BD444940B7E7A291C31BB476AE771140FBBF272A7FEDAB16C891ACCD01A430A872F0D910A309ECAC95C25C42AAB672E6A5794057786D3C67049D6CDB749633CC87F52A1604A054E1C45767D29B29F1197CB16395574F5A907BF6E2041FED9D3CE75BB738D8FD83C5F68455808DD72E3041CC408D806EB6CB39792A937AC1DA39574A035D901C5EF62B125EDFC249539DECB59719490497D6D56E0C4FBF74A35947D17B817B0DF13D5CE0D9AE8E13A4C7D3428CA81D33CBF159A3FA4C4AC43AD694CD94BCD2B426723DCB1FAD044D93A97B593E03E33FDF16E949C682CC26E80986A8E990A3EEE9FFD44B8E4C8932D8151A67FCAB29E4EC525D2289E7629B5D8213630464CF4F364CB2D45A9619C4B5A280A85E112C00306956EBD854D25DC4423F9EC4B93393EECEFA6D6055719CFCCB78E79F9C10DA9C8CD3BA0ADE29D0FB08D9B56C4B26CDC669B52E0270114FEDB38D56853BD1A59B1E82AA60B8F4E6F3AADE3185E4BF415147A5594B8870E1F140D55CFF27FE54D0AD8C6F341E11F91808BB0818F445FE8894755EF7&sign=74D10AD59C49795631FC73EF35ABBDCD4F217116 (Caused by NewConnectionError('<urllib3.connection.HTTPSConnection object at 0x7f08b3434c50>: Failed to establish a new connection: [Errno 101] Network is unreachable'))
### 执行结果
- **登录状态**: 登录失败
- **签到结果**: 

## 账户2
登录过程出错: HTTPSConnectionPool(host='open.e.189.cn', port=443): Max retries exceeded with url: /api/logbox/oauth2/autoLogin.do?appId=cloud&version=v1.1&clientType=20010&format=redirect&paras=4F73E3ADF03EFE6A50E1C77E4DDCD6D59AEDE061DDA1DECFEB3B64D6AB16FC2280EA6E615D081440EA9165B0730093BFEF3901CF3AA59CDD075C5C32EB729636E151F4DA2D7F387B784CC1C9D00420B07C7AC26C0A2DBF1E1880AA31000E1854D838C8A72A803142DC00E58EB13B141493D0A64CFCB3698D78321884314B715C39530F04CD379FDF7CA8C05289183A6E6E3018D385C1C864C7C2A0077942879B8209C30A2F77F2B40DA310D5598945B94AB122386981F1FE163E2D5665C6F31F1ACE412C2F14F9E121EAC69E2BC808A53D54A98CA90E93A59A89FCE064A43F095A0AE2746BB646BFAB7A1B7D926A563145C182C168EAF382EA89CFCCB3C3419B829570F739A5366FC93898A1D673A24E8F772D4740E7306D792C91F369B6B31B4456284BDBC2ABD5AC51F4A60B992CFE247A5DEFE28B1A189AE329E8BF44078D4D5016CADAD3ECC655E4F11C5C2011E7FCC96696719D9DA5E23DA60C07DFCF7C3D30F61664A950F9C9E9E3B3B574B785C347758091AFE419B2FDA188EC6280BED2705DA415E4B1E47A0942A197A7C46044B7B634951B05246D8157BE09038C2D33266F12867D286B0871DE018D83009C2AA8E646147A051854AB4695C7CC1B93E62BE3115716F730F2906E1A7106695707EA75DF767CD5CF23C6E658F44BBC781D11FC56A725346FCC1FF8BF435FBA5FE3392DAD413106DCE7F43D5082B220AC64ABB4727B3A54AF7EE872723E0B641DAE24E4C4F43968DF&sign=A93C4F61993AE02AACC756B194BC2826E73A9DD7 (Caused by NewConnectionError('<urllib3.connection.HTTPSConnection object at 0x7f08b3440310>: Failed to establish a new connection: [Errno 101] Network is unreachable'))
### 执行结果
- **登录状态**: 登录失败
- **签到结果**: 

---
## 执行统计
- **结束时间**: 2025-09-18 05:35:29
- **运行时长**: 541.26 秒

✅ **所有账户处理完成！**
