# 天翼云盘签到记录

[![签到状态](https://github.com/xdrive5/cloud9/actions/workflows/main.yml/badge.svg)](https://github.com/xdrive5/cloud9/actions/workflows/main.yml) [![项目主页](https://img.shields.io/badge/GitHub-项目主页-blue?logo=github)](https://github.com/xdrive5/cloud9)

**最后更新:** 2025-09-26 15:30:21 CST

## 快速导航

- 🔄 [查看Action运行记录](https://github.com/xdrive5/cloud9/actions)
- 📋 [查看最新运行](https://github.com/xdrive5/cloud9/actions/runs/18031112121)
- 🏠 [返回项目主页](https://github.com/xdrive5/cloud9)
- ⚙️ [手动触发签到](https://github.com/xdrive5/cloud9/actions/workflows/main.yml)

## 签到详情

# 天翼云盘自动签到抽奖程序

## 执行概览
- **启动时间**: 2025-09-26 15:30:22
- **账户数量**: 2 个

## 账户1
登录过程出错: HTTPSConnectionPool(host='open.e.189.cn', port=443): Max retries exceeded with url: /api/logbox/oauth2/autoLogin.do?appId=cloud&version=v1.1&clientType=20010&format=redirect&paras=E91F65C5A16E3D9BA2738427582B8C5F790CC79D61442C6565FC3D2BC91B1EB1CDAF23555637C6801261696398EC0D54867D4D84A5AD8C80F8A31419281596A1033E8C2C4614CFF23DCF95C68248680256D11C9900D5A605EAAF200EB2C8B2B72344D12E7F1793E5D97F2CA9DEACCFAB00BFF298788961A9686997FC0C0D9E55B9BF59304D7DE35934DEE6E3B0DF021276725C5A8D04E4CFC662A9E93372C785DB5B44130DC82EDBE1304882AC4B03E047DACAE1E5BF2937002D311C9E66F2D657249A5CC2A2355EAFE4170DE1EA99F76EB09D252A4C2F4D6A08D96DECE71BE461DBB12C676BD91AA12A99544577B18F0A2F86D08DDA6C33D8CFAE125CCF3479F0C42C756F1D99A495EDB64E120EFFD411B53AF9B8F777122E9EFEBF684A2EAE62F6A84F62996175AE3B6255ACF50C1A0FE0655926821ACBEFE5AC431AEA349643CC83A37B16B97BFABE47B3107CB8147AE6FEC2B614D15459FA469E3022D2C1B40A01EDA638253A16945D2D70D4A3279C1FD0B3974AF8A68521732632C2562869A716498346AE0F7CEEDA760E6B142411700E49862677E208A49F7432C4458DEFD3D53639191BAB7F05B3B484B73E503A2A428522B73E3B403E786E71897719ECBF50DB5FF5D45E196B7241EA94973FF958765E8F80A9AC63F681117C14AE60FFD2F5607331D6FDDCE12E456F20174F10E626AE7FB058468BC3FE8D64166891A8A29DEF08311E710C2C90F529E6720B6F8CCB5E46B49124&sign=A65BE46B5424EF6C9903F28FAFE6DC445A00DCFD (Caused by NewConnectionError('<urllib3.connection.HTTPSConnection object at 0x7f2a9bb604d0>: Failed to establish a new connection: [Errno 101] Network is unreachable'))
### 执行结果
- **登录状态**: 登录失败
- **签到结果**: 

## 账户2
登录过程出错: HTTPSConnectionPool(host='open.e.189.cn', port=443): Max retries exceeded with url: /api/logbox/oauth2/autoLogin.do?appId=cloud&version=v1.1&clientType=20010&format=redirect&paras=7251B015752174B3C7D2361251CB07E1DC02A297E789BBCFAE1FA71756026B73AD62AA1F84B03F2C721F952278CEA8796C0A793766A4E279691039DC5E0571AF475B7AAFAC80EB598867A3EDD0EFC7F0FE1430881942F272C1DBD582A42BF305D4FEED27DF26EB720BD63CF0FF68D1CC96AFC448022811E49D01C93BF7E6DF8062D35710E0FD4C213A77681F082F978F9473C48F786BB1DF5711125E59C73F0727A3B60CEDC666C24EB3A86CBAB3EBFDB0DE8BB5F1F11FA5D7251E875CB5F3F47054A06DA44A995D4817F8763147A19BB94C2D4F14878A8BFB4C5922E811DE1A24B8C5F8303225A508D4397FDE59A04DA4019B98B8784384742946D8BA958918EE9DFF855FE607905F7E7A3D3732569BBC20AD72BEC5375039858AFB6647C16A44A7AC87FDF53F5DE148B85A7A58B13602CC8C68762712B09F014850F41D591813D8318615BE5BCB866B3F8491626BF383479FEE66E10C3C63F9C8426EC8A43DCC5E172951EE6507BFFB0AFD5EC7D346FC7975410127F8FA565C756CD9C41358A86FDFC60E514879E8B62A573422E4466057B71285BB5F6CAEF237B50D2F1B377CF8D655DAA8BB2B5F19382A0653CC8FF735E666653461B5DD2424F8144D49FE8002E01D81A345D90039AC39BD57AB0011D4A630DD47163811F72D4ED641E97C510245364C90CE6731E3A67384C760B160F0EE088C4B2CCDBE46E3FFE83BB5AF3CEC108375D0A4F0E0A33255071510CFF0F3C46B7E8DA64F&sign=B304ACA823B10706197090AF71EFD760B590B608 (Caused by NewConnectionError('<urllib3.connection.HTTPSConnection object at 0x7f2a9bb63c10>: Failed to establish a new connection: [Errno 101] Network is unreachable'))
### 执行结果
- **登录状态**: 登录失败
- **签到结果**: 

---
## 执行统计
- **结束时间**: 2025-09-26 15:39:27
- **运行时长**: 545.27 秒

✅ **所有账户处理完成！**
