# 天翼云盘签到记录

[![签到状态](https://github.com/xdrive5/cloud9/actions/workflows/main.yml/badge.svg)](https://github.com/xdrive5/cloud9/actions/workflows/main.yml) [![项目主页](https://img.shields.io/badge/GitHub-项目主页-blue?logo=github)](https://github.com/xdrive5/cloud9)

**最后更新:** 2025-09-05 03:43:36 CST

## 快速导航

- 🔄 [查看Action运行记录](https://github.com/xdrive5/cloud9/actions)
- 📋 [查看最新运行](https://github.com/xdrive5/cloud9/actions/runs/17474923798)
- 🏠 [返回项目主页](https://github.com/xdrive5/cloud9)
- ⚙️ [手动触发签到](https://github.com/xdrive5/cloud9/actions/workflows/main.yml)

## 签到详情

# 天翼云盘自动签到抽奖程序

## 执行概览
- **启动时间**: 2025-09-05 03:43:37
- **账户数量**: 2 个

## 账户1
登录过程出错: HTTPSConnectionPool(host='open.e.189.cn', port=443): Max retries exceeded with url: /api/logbox/oauth2/autoLogin.do?appId=cloud&version=v1.1&clientType=20010&format=redirect&paras=82349CE0DDFC4582C46373597F71A24B71640891496743D52D2B842D3D8FD4BB6947A6D8B0C03E81854F2174DF69EE9F768A5F63473723CF8339C411868C312E1937F6174B77AE6E06A6F7838FBFAADB537D65F586A141DCF24C172EA5310484E67797269783902C194A6CBB6F21B8D5472A1066869916FE1AD00B3B07ECBDBA098FFB8CC16F47AB7295435F2D610F122617F5217927430AFD4A0202E7C8B6F2FACD5B46C59C886A241B1FB4F4B73B661BB7B377DAD515D956736553A6349480BB6DF93ED513DEDAE418E2C1D21690B57727AC2BF27031AD1CED5342CD46DD91934B81EEA497E73F74218C9D8AC33FDE8803B76BA0183575A0E67326A49A85C6F4F42F5CBDE38079D012E7D93D4C347AF604631EE3A1ADB72F17D169AB1C03D1F142A84B5DCA68BE8DC6E4FA77AA391FA762DFFC4CAB2BCB6D287A6C815927BB63F9C45035C56D70A549717580CBA9C5CEFD25123E0A492CE2B4D1EB77B5DBC73500DEE9728CD2B48FEA39A4290AE5A40DF4DA9248757460C6A54B02894BD4424D13C7E785752815A39BE5EE835700195E7AD287D88BEE7195F84B8A127566262B4398640B322A8A0B9B4F875DDD2A73A8D24242FF6ACA07B1E9816B9158286F8719E3E23F424ACC6A471FB7D047D740E6FF3F820AB524609AE38239265F8580D365D69852C06B2F3BBA1ECD1B346E0BDBE8E337EDD336CF843404BD520803B2B0D877AD7702C8CD992FCCF126A83AC95FC0D8114995C148&sign=02E3D976A07C6C35E55185B01A9B0CFE9BEDE8E9 (Caused by NewConnectionError('<urllib3.connection.HTTPSConnection object at 0x7f04b4e308d0>: Failed to establish a new connection: [Errno 101] Network is unreachable'))
### 执行结果
- **登录状态**: 登录失败
- **签到结果**: 

## 账户2
登录过程出错: HTTPSConnectionPool(host='open.e.189.cn', port=443): Max retries exceeded with url: /api/logbox/oauth2/autoLogin.do?appId=cloud&version=v1.1&clientType=20010&format=redirect&paras=F8DB691342FF7334BA911BCAB0998C9523A4DBD94CFF88EA391522224CEA1F2B18E4D0B1B991FA2FD494CCBE4DE6976E33D7A97377C862BF9F2F4A2F2A124C2FCF17E4FBC49DDBE7F17CE96496CB1DE1885E9476FF91BB6D5CC43C8CA4AF6B7AE106849583A9B88E7E36E49FE84E1D333857157E8B400ECD2ADC4B76E56E24FD3BED99BF4814246A0142CBC9EC2F1F521BA644A745A8E06CE6A3557237A9B9EA011B9B8632229C014C1721F05AEF66EE3DBEB7C9AADE42523816FE55DD3069B9E32C4A487DED6EE77796CB77F7C5D321FDCE659B9362FEC6ECFB8BF25D7AD666F880E7ECE8F539D235FB43C15C1DF9CA7966D6873F4997F0256FBD8358C4DF6F87C16AF7282D2EB30F415DFE89F944CD0253C81B42FB2D24946B227F09B7B2D28C2EB4C399894240FEBB2583B257DDFDD5C8B9B19E8FE9220073BE2DB0E278FBB9CC72C3D42BCEFF357A993C617E1FF2505B3C2E1DF727D3D9B6544DB9A8DAE6D83DEDA79C00C89927D5425123FB94D13E1BA22A54BF7B74826E5C82605095CBE9F3DBC036BD7FED24704F1564C827856100D765F98F6B954CF7B6545FC360FE3922396CB843FCF5C9E0243F859BDC84AE9BFB91F2CB5DEB77C0C8AFD8D5194681A199F8CB4073121BD939190CEC3DE37413DDDE737078BB2AFABA1C23F82B6CBCAD8F507DBDEBF708D576F95C302FEC1ED60AFD085B10BF6206373BBA093742BA6D32904E3D74BFDEF0714F9FED312C552A4A6E7D08C632&sign=41F02DF52DA29F2257298806724A1131054F153E (Caused by NewConnectionError('<urllib3.connection.HTTPSConnection object at 0x7f04b4e33f10>: Failed to establish a new connection: [Errno 101] Network is unreachable'))
### 执行结果
- **登录状态**: 登录失败
- **签到结果**: 

---
## 执行统计
- **结束时间**: 2025-09-05 03:52:39
- **运行时长**: 542.28 秒

✅ **所有账户处理完成！**
