# 天翼云盘签到记录

[![签到状态](https://github.com/xdrive5/cloud9/actions/workflows/main.yml/badge.svg)](https://github.com/xdrive5/cloud9/actions/workflows/main.yml) [![项目主页](https://img.shields.io/badge/GitHub-项目主页-blue?logo=github)](https://github.com/xdrive5/cloud9)

**最后更新:** 2025-10-09 05:29:22 CST

📋 [查看最新运行](https://github.com/xdrive5/cloud9/actions/runs/18358575553) ⚙️ [手动触发签到](https://github.com/xdrive5/cloud9/actions/workflows/main.yml)

## 执行概览
- **启动时间**: 2025-10-09 05:29:23
- **账户数量**: 2 个

## 账户1
登录过程出错: HTTPSConnectionPool(host='open.e.189.cn', port=443): Max retries exceeded with url: /api/logbox/oauth2/autoLogin.do?appId=cloud&version=v1.1&clientType=20010&format=redirect&paras=8708FD4697AB6B11993E832E2653B4B3262116407AC0A5CE7AAA659380DC35530E36216AA314BF5342D28503C1F6E3D56BD8CAE2B745B1950A86CAADF43CC9B8C3B3CB3C6473F8A230150DF333DD24BA7305043A30B722EE4889214644603DC405346C1F5CB191AED8CAD2DD6F28951B3E772C14C2F9427116651051750A957F6CD8B004AB17BC7A5688CF22064808548D25020FD5FCB745AAF53A52B64629384A27130D3ABB5D007D93A4E67C633ED2EDE29A249AB31455821DE8FA48948768341A835E7829963D42A78238351FE871D0401818998E08AC950603B6C8D5C9A982C535B08E78AF4EEC69EF74931542BF6F6D00E7184D956A04B60B1B705C5E4AD368764A16AC0C5017EC74BF09F0B0356D8F291EE9D45A37395AD1CAC540E9E6DD0C26DAD8261F8A975F2D881D8BFD9F7166470EF9A7AEE850F95946B43A0C358885D53AE034FBF196800E6544247D75DBD95EFEA76CC37264A1EE9C4C8429C6E0B0494594273985F11A5128CBA244170093F2116C0B1887A4E675BDFAC3C16B77C77DA096787723C50140ED6450A1C3CF8D31E0B5A1C0F90E9DF184281A13E010EE690EAEDDDA1665B0200AC154CC9B1E10EBAF56CE5DB0CBE803035B594839890576FF46F7B9E2BCD3F93E2A6DFC694D194E5E01E5CCACBD3A6B2C378DA4199A9D68F2E6A58703F9390840E7584542E4940221C3D4A96890278628B9BD482BBEB2FFA57C5482F97BAF2A6031ECDE47DB115A43E3A7E941&sign=3E27563B79F482E501A7A42B302208392FC27802 (Caused by NewConnectionError('<urllib3.connection.HTTPSConnection object at 0x7fdd6ccc4b90>: Failed to establish a new connection: [Errno 101] Network is unreachable'))
- **登录状态**: 登录失败
- **签到结果**: 

## 账户2
登录过程出错: HTTPSConnectionPool(host='open.e.189.cn', port=443): Max retries exceeded with url: /api/logbox/oauth2/autoLogin.do?appId=cloud&version=v1.1&clientType=20010&format=redirect&paras=9C674950B80622A4147288EE6340E9A92C6349E68BE40C1703B9422EC0A432A1D64C889ECA10945B6CC67490266AFCD3DF0C87C2625AC9705843ACF06B434F399F9ED17B7C31B9EA5C7E6D6A5F102EDCFBE0760E9D1C672DB31DF83859354DF9C158840168F34A353B0AE8C171B5828ABC0905E8594552C5564ED7A3C2237543F815E197412D6CA22FD4B844F5686BBCCE6F883420C8F3799046CA68E79B02E2DC9B9AF5C77410B28B6E33DD58145FCEDBE17CA3E8A5A97E41747A928BE58046E68ABEE8A9D1D8DBEE64700445D7E19D6D9EC24AE023068F799C15F809581571BED9B3B64251309FEF42CBDB110C9C51445E0657DFEE71051222A2AA09C74B26A651DDF2EA0FB4272D3FB97C0561C5DB3578AC8034902D9B1615C6224403FBEB3BC05D4C74FD5F368600AF3F99332A006398C90A7AB85F21C4C7DD07BDA5FFB7D319F5748F6C2B8113DEDE9B14A88C6DB4BAA7937C3FF46415E2712C5A38FC22AB6013297FD11B8A2E368C3D66BF495858EF6F0A977E48C10DA2A44BCACA9FFC34AE5D0EC594B335AC37D718CCA2C79A6E50C5B5B734389416A8351EC9415FF809AB9A4A8D50A25B3910E6ACC3B8B9042724CBE182C0E78F090584A6D6BB42E5D37B8D7B0E6936847A3E3EBE97FCB04DEDF5AD3E01638D6A44758CD3BCFDCC03D13F86D2D31DCA252F98F18148629BE0149F415EE20AC5762B0323EFAFA7C2F158D61ADBAC6C651DBADBF9C062AA8E18F5AC2938EEA17D8F&sign=9FF6A1187737F032575BF312D16377F24065C6AD (Caused by NewConnectionError('<urllib3.connection.HTTPSConnection object at 0x7fdd6ccd0290>: Failed to establish a new connection: [Errno 101] Network is unreachable'))
- **登录状态**: 登录失败
- **签到结果**: 

---
## 执行统计
- **结束时间**: 2025-10-09 05:38:26
- **运行时长**: 543.35 秒

✅ **所有账户处理完成！**
