# 天翼云盘签到记录

[![签到状态](https://github.com/xdrive5/cloud9/actions/workflows/main.yml/badge.svg)](https://github.com/xdrive5/cloud9/actions/workflows/main.yml) [![项目主页](https://img.shields.io/badge/GitHub-项目主页-blue?logo=github)](https://github.com/xdrive5/cloud9)

**最后更新:** 2025-08-22 03:43:31 CST

## 快速导航

- 🔄 [查看Action运行记录](https://github.com/xdrive5/cloud9/actions)
- 📋 [查看最新运行](https://github.com/xdrive5/cloud9/actions/runs/17137297167)
- 🏠 [返回项目主页](https://github.com/xdrive5/cloud9)
- ⚙️ [手动触发签到](https://github.com/xdrive5/cloud9/actions/workflows/main.yml)

## 签到详情

# 天翼云盘自动签到抽奖程序

## 执行概览
- **启动时间**: 2025-08-22 03:43:31
- **账户数量**: 2 个

## 账户1
登录过程出错: HTTPSConnectionPool(host='open.e.189.cn', port=443): Max retries exceeded with url: /api/logbox/oauth2/autoLogin.do?appId=cloud&version=v1.1&clientType=20010&format=redirect&paras=CA3BAC48D446F149E4CCAC6FE8CD834C50D9D5403FDDF46566D320DFC1AD5A1EFEE94273088F2F9865B45493F773277FBE161AFCE4F7779D94D28FA6D0BDC9740A51FE63438C1E829F1D6AC580112BA05B08D70C2715220499087D9C76F3F02DA927751B0730C56EE48F297A453DF0665870BAA558B05A82360A718A0E13CE9AE0ADDF4EABBA1790424E76A087BF10CCE9B7DA5D6D54C94A30CCE6A823904C6BF9648D6707834A65F6ADCA015762BBE874791D6BFC7FB21E77BB21999093976FB85ED70B21EE172D6EC18258F734F2DEA6EA5C66EE3B1755B91C83C734FD0276EBA9C95661EF20287EED05E1615F3F921DE13EF9FFCFF5ED0FD0983BBE55A0E67D704DCD440DC0621531A2CCE5F84700FDA0DEE8D3F45F8A2BAC60AF633FE9B7880ACFDB51C34E19C92E9FEEAA6281D799CC68D8C50210FB0E29485FAF8100F3F454F1387E3E07CC264CAC93D482B1C6A7FBB05C0AD9B82E3FEF1F93F274FF97F2EA41E5EC217B77308D6BDC70F0F49B543DAEBD42BDC86A732004DEAAF8F1FB6CA1AE35845AD1CB90196D1C117697F265322F9078ECDF8B3374EA57E613745CDA3D71DDDFD934C8E0D6F59C2BB0F4726A7DED22C612DA10C32DF4BB3500B5E6F860F3F6A451D54FFA39D53EBA2A19FC4384C64C69BA8E654E2F01E8371B9590291EAA5852B14605ADEB21E2B633ADF4E0A3B3D02CC4C6CBC60D14D5A5CB2BF0CA452BC643CBC8CDABDF2A9C3E7771E3266964EA9E4D8382&sign=B1D4AAAB574341855F6A6ED8983B147175106C4A (Caused by NewConnectionError('<urllib3.connection.HTTPSConnection object at 0x7fe240d30890>: Failed to establish a new connection: [Errno 101] Network is unreachable'))
### 执行结果
- **登录状态**: 登录失败
- **签到结果**: 

## 账户2
登录过程出错: HTTPSConnectionPool(host='open.e.189.cn', port=443): Max retries exceeded with url: /api/logbox/oauth2/autoLogin.do?appId=cloud&version=v1.1&clientType=20010&format=redirect&paras=5FB50A9A526AF3CD591CEE10BBD7FBEDD9A7822E3F0A6CD250D50FFE8F102629D7D2881A9872D2F44A9104A54056688FD99176BFF6038ECF9607937CF64E1198E56B9B8A074F16DF363D14DAE89B4D730F982230314C9B70564926412CADD8644E986B5C5C58AB8C6D25344492498E999A81590EF9A05737D64D025D4B3B11D47ED372B35542C235651FB45854A9B1C8E7AE35164B6B19B4F92EDBC521F1AC1374E1AFBCC134F8694CC66F29E8B725763D221DFF19E8E1452880E9C5102240D25591399672E75BDAD2341E08C9D895EF9DC11765722B40D2B820593C50AB594532ED644229DFB452E7AE609F7B9201CED7FF027D5528B3379ABD500114818065405CB2C8AE18E32E5FDE03833C914C0D154F90F535F5D9090AA5B627C408B156929D62F981F6F2A38D690EED74C68371C7CE072E87DFA7B6EB8CA2FF2E49F9E390C55481C8AD5C9EC73DF92C61B826632352CFAC9DD9F85D98F7234E8FF358AC681D666B32F4449AA0810F499A6E496B3AE662DA75879E79E8753CEA3CAF45D47DC623AA03644E1A140DE00960F61EC4CD7F2A578C4664933B871CAD052FEDDEFDF22BB771E4F0CC343C08BABC22B011C11401814BCF4606D37E8E490AD0C0622AE491B25AA83327A006DEF398076ADC54D26CD853F53A2FD9E9B2B7F1329DC9544C038DE211AA642AECE524E3572EB25EF9A508D762BECD3A22B2E04BE00B2F5F8154521176EF031758A87E5A457AFFC80B1B428F85165D&sign=F5BE42B0ED38497A2CC8E21FB42AB3EA8F523989 (Caused by NewConnectionError('<urllib3.connection.HTTPSConnection object at 0x7fe240d33fd0>: Failed to establish a new connection: [Errno 101] Network is unreachable'))
### 执行结果
- **登录状态**: 登录失败
- **签到结果**: 

---
## 执行统计
- **结束时间**: 2025-08-22 03:52:33
- **运行时长**: 541.07 秒

✅ **所有账户处理完成！**
