# 天翼云盘签到记录

[![签到状态](https://github.com/xdrive5/cloud9/actions/workflows/main.yml/badge.svg)](https://github.com/xdrive5/cloud9/actions/workflows/main.yml) [![项目主页](https://img.shields.io/badge/GitHub-项目主页-blue?logo=github)](https://github.com/xdrive5/cloud9)

**最后更新:** 2025-08-31 03:43:15 CST

## 快速导航

- 🔄 [查看Action运行记录](https://github.com/xdrive5/cloud9/actions)
- 📋 [查看最新运行](https://github.com/xdrive5/cloud9/actions/runs/17347844819)
- 🏠 [返回项目主页](https://github.com/xdrive5/cloud9)
- ⚙️ [手动触发签到](https://github.com/xdrive5/cloud9/actions/workflows/main.yml)

## 签到详情

# 天翼云盘自动签到抽奖程序

## 执行概览
- **启动时间**: 2025-08-31 03:43:15
- **账户数量**: 2 个

## 账户1
登录过程出错: HTTPSConnectionPool(host='open.e.189.cn', port=443): Max retries exceeded with url: /api/logbox/oauth2/autoLogin.do?appId=cloud&version=v1.1&clientType=20010&format=redirect&paras=44F599BB40D0F5064D5D012843EC6028AB5C8BDABAD180D21B7A27B55987E812FADC50DFCAE3D80DA0BCA953CB2FCC12389F77F4C7A6FB6CB5E0AB1259199FBB245B43FFDE20DA439DE8D6E9299D2E5C39DDAA2437A5DE7D0EAD7D63ADDC71934C4B5D9AB942CB30DE14325C24A0017FB73400AEC93788BEB2CE7D3CB649F9ABAD128457A66334A4BAE559E23A7F29E234A461D7604C1290D185C697A79C2E0084DD5091DAC9C628EDB7BA185B95E50BE13123B9EE5E434BAA799D29FF844B879CED389E4AFEE5E78DCCAF8FBBAB6CA2276E08B4AE1AD85CE559ED46A074CBE8AF3BD01F1BAA9740EF00762D707C23C340C97DD566394453443D69AC9A4D8C3891F73937FA5CC0D226D4357BEE4D3BAF59893BC6D2D8552521A3DF6A9F92C5118C983E367F6E89D6CF2C2E8DC6A6741548C99D6697D90B9DE540385DDA005E5F832744C300E5DEF2CA907F1298EF691AB526DC9381309CDC5AA24AE8E59FD9FBB5C584B78DA6E7245784F95B21FB9ED89045A6DF65D9A10012DDAA2D3AEFF9F130EAAA5A34081A94F5CC2E6CA5D53049D2EFA743D103546C38011576288A224FE53EA5DF7C3BE92D5018A072C01D5A5018EC49822E4686B2F5F9B4B9FF459FC7381E666A192B353856F96A4547846E6ADEBBDA0CAE8E00AAAE2F7DF05D335E830D85ECC6631FCB868129F20FC23B06C456B366598BF0DCED3F8BB0C67DF82A531E4B053FAC231368124D32AF2CC9C822B6099183F34AA223&sign=B23F375EB34425A39FAEE20B34A9E9CB957A65B7 (Caused by NewConnectionError('<urllib3.connection.HTTPSConnection object at 0x7fe76086c9d0>: Failed to establish a new connection: [Errno 101] Network is unreachable'))
### 执行结果
- **登录状态**: 登录失败
- **签到结果**: 

## 账户2
登录过程出错: HTTPSConnectionPool(host='open.e.189.cn', port=443): Max retries exceeded with url: /api/logbox/oauth2/autoLogin.do?appId=cloud&version=v1.1&clientType=20010&format=redirect&paras=666C3B04F2378DE2C11515A0A2A5C8AD29B5CFD420A7EE75D82E8F09F9C2C5C14E1F85FA6B04B10470D0E658A4792CD7E7CD08192934E9E29B3A1E47E730CE2918C8994AD3C384104CF9FAFCF758A9D5A58D437FFA8D80D11B56B520C4DCE58B22AAC9A292F1D0CECF1D2B1AF978BF38A0C07060364DBDC031F4F67C10FFD350AC48E6D32F7FD159A31E08C7F174A542584C5F7B74D1DD40D65272967B3C4168859B412CD5827F0FC71077CAA79793B0542AA1CA0D9EBFC9B53CE7C822C0513614845C86EFB1CD81560295CDB6D25452337D3221A2D1E6775742504E4AF2781FA324F3D2475B9D523A777A77C3131799B92CA88A17C50B384CAEF2ACC8B0F0DEFA0145E6959B10045BDB736C44F3E8577CCAA8FBFD68B4840648CC0CA3E52294182A1D6C313E4D11A43595DCF5AC1CD87C27E971608516FE9B896285468DBD77E742BC5C08DED2C01FB4B0031BFA8B04BF8B3EBC69659396D0A7DB171FF6A9E4CCE39E38E9B89671F9A5C1803DC041435104499D5E29A3795DC559BB5484012A478D543CBD5F272501476D41A16BBB60EC37C9C309B96F6FED500D2943488A4F9302613E2D1D8425925F7505DD22188F0CB4A5763CFE4BF1B874910602E2C33BA280F97716BF2AA99758F574D6745F6568E09487C91123BED53F18616D371B34E01EF0A80A3AEC9786EE8C6739035E936A44F3764C7F69A00BD1AD777BF8DFA967513C216B9DA22305C07039258FBDDA94485A3D8E998AB6&sign=7F827C8D24202D401DC08A427A0EA566486C5931 (Caused by NewConnectionError('<urllib3.connection.HTTPSConnection object at 0x7fe7608740d0>: Failed to establish a new connection: [Errno 101] Network is unreachable'))
### 执行结果
- **登录状态**: 登录失败
- **签到结果**: 

---
## 执行统计
- **结束时间**: 2025-08-31 03:54:31
- **运行时长**: 675.65 秒

✅ **所有账户处理完成！**
