# 天翼云盘签到记录

[![签到状态](https://github.com/xdrive5/cloud9/actions/workflows/main.yml/badge.svg)](https://github.com/xdrive5/cloud9/actions/workflows/main.yml) [![项目主页](https://img.shields.io/badge/GitHub-项目主页-blue?logo=github)](https://github.com/xdrive5/cloud9)

**最后更新:** 2025-10-11 10:07:34 CST

📋 [查看最新运行](https://github.com/xdrive5/cloud9/actions/runs/18422816510) ⚙️ [手动触发签到](https://github.com/xdrive5/cloud9/actions/workflows/main.yml)

## 执行概览
- **启动时间**: 2025-10-11 10:07:34
- **账户数量**: 2 个

## 账户1
登录过程出错: HTTPSConnectionPool(host='open.e.189.cn', port=443): Max retries exceeded with url: /api/logbox/oauth2/autoLogin.do?appId=cloud&version=v1.1&clientType=20010&format=redirect&paras=305CAA64C7166E64E1AEEB070E29D7983509D2AE253E45D43761100E7D08990F3F3AE11F7CA1DA8D7417E63783FECF44B6E403534DCEAC95CD763C92E169CB98834E435CB1B6B7F99AC3C29664AA4890828898DB0AF8671E98C78B7AA70688464E1347E9BE00E60ECBF98368204682AF79C2673A3AE5E7E9F301E7EC72D9972D13F1C3F31CF38BE2BEC82AD9B7F72A494C150059A565AC9EFF68D5A9DD0BD982EA9DE49BA4596F446D0079FCF3E3870CAF4A90ECC362CBE1923BB279BA38960A47D6C476F537EDF81439AA07FCD7AF9A555F82B4B586D1DCD54754905FD724E639080D92D55633B922CC1404BDC85DBD75374B9D831809B71E9DED1EDCD3E3BDCA248A0C7382E2D122F7EDEBEB186B3D5C010D37E32791C3D156CD2B75FE679E6EFE54E35AA7B00D0210C40670F687EBC6189E687BC002617510F01B1102A6811133DBF2EA000B649175660362E1EA2A22CB59998C0500A4B2ACFE8E4B0E1A916C7C43C08488E923B18612F785DE0229CF66FA1810B6ED1EEEA70537A87435F128E13481BF4138F4CEA15682379AABA2AFDFBCB8B3FCEC5BB9B2D802CDC7D66F01D9739489C4674CE4DEC4699E87F3D841F0651BA35B4C1B797D1E4E063F6F5DB88799DC2F6337BD9C77A9C9FB0EC9BB2F961C87C831709951BD54BEEB939C311F3AA9EB905E914F16D856A7DD4360E34310B6C03435B6B1718578B3D6F21A92E3349958CCD77D5DC5CD5D364A5B85B22EBE2357A37BE099&sign=A45E94DB9A49DBA0304AF412643E26AC4E3BFD41 (Caused by NewConnectionError('<urllib3.connection.HTTPSConnection object at 0x7f5081bbc4d0>: Failed to establish a new connection: [Errno 101] Network is unreachable'))
- **登录状态**: 登录失败
- **签到结果**: 

## 账户2
登录过程出错: HTTPSConnectionPool(host='open.e.189.cn', port=443): Max retries exceeded with url: /api/logbox/oauth2/autoLogin.do?appId=cloud&version=v1.1&clientType=20010&format=redirect&paras=A7F92CC382CEE30D87E126133939096496E3C63A2A5B9F1EEEDC308959D4D3F5ACBE0E76BCDAA99216510D27B8B4A119E5BE65A03B7A9229FE50AB1D0942C9CFB5EA408BBD29D06A9D8E6F0C53F587EF06CC52D783FE4A50F9B9CCE13FA100EE428DE80E3822C773B6DCF8910F14DF062834DB0825DD01AD774E7E10CFDD3CCEB57A6219C83E74CDE5B342EF42B23EFEA520C97E9AF038C404E9653514D91B26E9757811410BF8CA709760F0B3693C58DA2A1636282BD423FF5E8BCC57FBC7B92886DF809026584DC4BE6EBDD3FA45C97AEF764071212F1B2AFD65DB09B05B77791314B44617BF1C13C40C9D71566E8A71CC80772FBC9779B28033CB18B350D06F645F0802A98370E1B9BC4F3DD9E28A5D211E0DAA43D6623AAA28D953CD4E5EB91048CA2A04598649547369D6DE9E7EA6C0C41A358818CCDCCB639A3F21DFC3548B722C8D2C36587D67CFC86206CB58DE52EE31ADAED5AB04A289E7BE7B874A449EDD1396F7BFAA030889627F6D04F0CD1ADADA6FF03C1E3969029047C79268A3100BD75C80EE0091BE9624C2343E64812170E693CA1354B7C89DDEA32AFEBE16F26929903CD1A865B7B09816CA3FC6EE0EED15B18D59044C288AE2C4416C1A6EECD09A6E25C8CF894250D95D34FF73C511098C75E224F7579DA3C5C2AD9C87E2B85A85B92C429BAE05BF41AA48564625820B1FB4210045B0AF2E6B67C88B81B9E61AC825673D82B62A181737A551DDB4E4902FA18C8B2B&sign=FFF097665F47B097DCDAD4DB8D6E34E7A494ABD7 (Caused by NewConnectionError('<urllib3.connection.HTTPSConnection object at 0x7f5081bbfc10>: Failed to establish a new connection: [Errno 101] Network is unreachable'))
- **登录状态**: 登录失败
- **签到结果**: 

---
## 执行统计
- **结束时间**: 2025-10-11 10:16:37
- **运行时长**: 542.89 秒

✅ **所有账户处理完成！**
