# 天翼云盘签到记录

[![签到状态](https://github.com/xdrive5/cloud9/actions/workflows/main.yml/badge.svg)](https://github.com/xdrive5/cloud9/actions/workflows/main.yml) [![项目主页](https://img.shields.io/badge/GitHub-项目主页-blue?logo=github)](https://github.com/xdrive5/cloud9)

**最后更新:** 2025-09-28 05:26:55 CST

## 快速导航

- 🔄 [查看Action运行记录](https://github.com/xdrive5/cloud9/actions)
- 📋 [查看最新运行](https://github.com/xdrive5/cloud9/actions/runs/18065161777)
- 🏠 [返回项目主页](https://github.com/xdrive5/cloud9)
- ⚙️ [手动触发签到](https://github.com/xdrive5/cloud9/actions/workflows/main.yml)

## 签到详情

# 天翼云盘自动签到抽奖程序

## 执行概览
- **启动时间**: 2025-09-28 05:26:55
- **账户数量**: 2 个

## 账户1
登录过程出错: HTTPSConnectionPool(host='open.e.189.cn', port=443): Max retries exceeded with url: /api/logbox/oauth2/autoLogin.do?appId=cloud&version=v1.1&clientType=20010&format=redirect&paras=0AA399B89A81BB88EC5C0A0EBFCF2E4C3C1C0AA34AD98C563B31955F98ACD7B4C84D99BBE5450011575F36563BC78A27767557164F03E8C48C0CF4CEAB673449CE0AE26A8B8BBD566B41CF2BCFAA50FD9BA4B4BF1671AAB778BA7730E6633E904367FC21004746B3DE9F8D09AD974E24BC4AC147C1DF46E2C8EBC86B155205208046EC87EC7215B482839EDF518EEE34F4D8219E1F997B3CBDBA6351BA84DAE405724A00788183674407BC1DB381A1DDF993FDBC22EF3ECB7A2668177D2C444EDA25F4BDC77B1BF705738CE2E2B6778DCD682D2E9469F65316475E4E91A8B904478370A3304E20D30ECF10F054FADA263DC9720253F5BC8A07682BBA93720816EDBC9CA9CED30157B3418E0B6C1A82C90B5160DADBB0F68D5BD20CC91334C452BD6CD2830230E58554CBE1DCAD507E9601CEE84DF8187FF3BE008AEC779EFC3E768D2249BA7F48E2F6FC292AFC3FE060A4C085DD458482166BAB619BDA5974DCCC3363AADC526948A12203C1E749490F0CFD7D24E3CEE91960C5C11A6A80E65AD762367E35DC15912E9C03260AF55DD37F6836D8A206889058EB1154F08D4A8C77CBDCB154A5E2A016868F4DFB52104D127BA1823E92B4394DC0B275537DE9CB45FDBB43C5CED5EC9356683644B5C78074AD10FA8F84B64A8C7B7A77A52DF184A28CB2BA675BED7FB2B637E942C05AFFA97FE7F40A38AE899DB837E2337AAD776D2DC0453F5CF9224D301D9CC1BF3B7D7E2921F3B01FFC7C&sign=A8C88C18CD2B3883C4E63C8143BF71991E9E3399 (Caused by NewConnectionError('<urllib3.connection.HTTPSConnection object at 0x7f6df49a44d0>: Failed to establish a new connection: [Errno 101] Network is unreachable'))
### 执行结果
- **登录状态**: 登录失败
- **签到结果**: 

## 账户2
登录过程出错: HTTPSConnectionPool(host='open.e.189.cn', port=443): Max retries exceeded with url: /api/logbox/oauth2/autoLogin.do?appId=cloud&version=v1.1&clientType=20010&format=redirect&paras=4151CDA9F6BD8C4E1A47D5928C6D253312428F598A53DFCDCB7F570EFF2E73466D66D14C6FAAFF6A4F49579C77D8423A2005667A60149105575D0858E492E30272DCCBC8A794AA956E4E9B2A8F9D08C1A3E49B0936BD6440944F0C223B8A6E3B61DB403CFDDB4F5EE0DCE9AC730FE94074AA2ECAEA478C198629928FA5B334B1D130271A99105B60EE6F2266D4A1A5C0648C25E726ECCE312EDFF15403E76430D47C5F9332A1EAF254C15FBEA84DD28A8219346DEF68172A7F69CF60AE935F8A83D6FCBE9E3B9F0C9919C15AE0C319AA9D3B7C58B3DCF33055379725762FE3F79FFF37733FC0557A81631C65D92DA8EC5FAC140117424DF67A650998B32A3B3AFD8353BCAEDD294D4F452ABFB87D11A731578C10211AD808A35ECC47AB9CC07274120565FFBC1F83B0748692F2F31013DD3E087649099A3D887297A6553D37BB84DA4E44270978AD53443FB3BB0C6BD04434A0021D466DE5C2CAE6F07877F4DD062B5EADA1FD859E699E4C15FD2C97D859B159B0D60203555A8D5421214CFF870117CF4B9FC20F37BCD5682F160DBD3174F0C022D67E75D16C5223CE6008653391F8133728E1DA9C6AA266064C927287ACDF4967D624536660457BD0F0A8C98F12A1A5EC35775A3BFD3B3830F8CF9BBC9E96A9BFAAF3F12C578318A33C9C119AADBEBA74B37098478CEF7A7CB28D7C2493A860CE459E0A2620955EF4C293BB8FAF312D3724A0208F2F4B36AA08DA7D01917D769CD0D61274&sign=0EF8EE2C1E79C6C7B02BF03580B92149D667F809 (Caused by NewConnectionError('<urllib3.connection.HTTPSConnection object at 0x7f6df49a7c50>: Failed to establish a new connection: [Errno 101] Network is unreachable'))
### 执行结果
- **登录状态**: 登录失败
- **签到结果**: 

---
## 执行统计
- **结束时间**: 2025-09-28 05:35:56
- **运行时长**: 540.56 秒

✅ **所有账户处理完成！**
