# 天翼云盘签到记录

[![签到状态](https://github.com/xdrive5/cloud9/actions/workflows/main.yml/badge.svg)](https://github.com/xdrive5/cloud9/actions/workflows/main.yml) [![项目主页](https://img.shields.io/badge/GitHub-项目主页-blue?logo=github)](https://github.com/xdrive5/cloud9)

**最后更新:** 2025-09-06 15:43:17 CST

## 快速导航

- 🔄 [查看Action运行记录](https://github.com/xdrive5/cloud9/actions)
- 📋 [查看最新运行](https://github.com/xdrive5/cloud9/actions/runs/17511839396)
- 🏠 [返回项目主页](https://github.com/xdrive5/cloud9)
- ⚙️ [手动触发签到](https://github.com/xdrive5/cloud9/actions/workflows/main.yml)

## 签到详情

# 天翼云盘自动签到抽奖程序

## 执行概览
- **启动时间**: 2025-09-06 15:43:17
- **账户数量**: 2 个

## 账户1
登录过程出错: HTTPSConnectionPool(host='open.e.189.cn', port=443): Max retries exceeded with url: /api/logbox/oauth2/autoLogin.do?appId=cloud&version=v1.1&clientType=20010&format=redirect&paras=2F44AD0B57400300450981C0222BDDDE57B57FADA01A44443210C3C24DC089F174E9EAB94B88DDEBD661F74BCD2D169DA83DC2D505164B4757DD792F4B1B1DD16079DF4C7C8893AC75E0A1C3F9DBFE1F4DD45FA2D14B75ED269C1792F9C2105A2F95881C42FFF7591B31CDD229A3FAD7AA02D462FB792841949D473C62D4ECD165946BA18173CED368DB3448D6DA913E0280EE2A54EA61005164C90CBCCEED2F9297FD84FE1B631B4B27B0142DF02F5F3BC51A0DEBD3934D04282C21EBF95E89D3CBFB3C53A3690D1FA9374245E0534BFE7DF1593418CBB7399111B78036045A849E7B883D5B4EE680FC715569AB314FE4C234988846A49C8DEC861C4FB4CE900F22DB8608CEF8FF56A644BB860BEDB3C394CEC748686CFB86C627949A096F00882A2B4B9C25C1E511D4ED55BAF9A1AE97F0754D45C41C1AAC9F54F5B18D96006D3E6648A012A32D5ABFB8C707453159B2FC96693AD17C9C979842A6DA5EF3187D3C3C121D328BFA37D543CA0B167084E8441B71DBF7E2CEEC81BC28A88B2316C8B9E7D901AEC122978EBBAC2F9AB208015E7550DCA6202AF9D924AA09490F75C07B13D5A45FCB45CEA8F149DE3BD6DF1A7FC20BD9036CE860C8C80D13188387D6998EB4E3FF24E6E2F7DF5E5CE4D6A019868A67E3230B68981911BA899F854C8541F5DFC48B894E7AA1A5EBAC5E4C3164261C0B2412624B7B9DB70D7878CCEA11A876726BA99E6F48A75BE1D28806CBF7D84C9909C02E97&sign=D5F224C1B3AEA33FA2580F5C4B7C091C7584CE21 (Caused by NewConnectionError('<urllib3.connection.HTTPSConnection object at 0x7f180d4d8350>: Failed to establish a new connection: [Errno 101] Network is unreachable'))
### 执行结果
- **登录状态**: 登录失败
- **签到结果**: 

## 账户2
登录过程出错: HTTPSConnectionPool(host='open.e.189.cn', port=443): Max retries exceeded with url: /api/logbox/oauth2/autoLogin.do?appId=cloud&version=v1.1&clientType=20010&format=redirect&paras=C11AED5BB0F023584449B351728B9AF5C3574C505532359CDB47EDF0404F09BF93F8E31D61A357F2B780230839694E9A7C37A029E55E9381FF715872D5ED9BD4495F6E77E9D28D8FB810D8F3BB928C3D1C513A2B68697BA612A64C46C106B1CF0EC8ABD29B3AA5F4C7C520B65A91CFDB3E88BFF7DCA3713AB2CFCB23461890502D6E3B968442E844C319BB440BB4D6D8B02F27C5AAD36ABF926E981D78F7246C4B7CDA024EEB067BDB40F67D5BA37F41197E2AE82222D92C95EC165927555D5FAE819AD693C033065312048E68D41FD07CD5D03424329666666D81E1E75D89A1F1A85E0FABA81363FD91DF19FCAEC40355D6529E9D6029B8BD1F23FAC803E2A5342A0EB7FF22A5D2D5F4F85E16A3A041CB78D2DD59F9896C70ABDF7158F58333C533DEDEFA1B0959AF565688270FD6519E9516B8E3A970F67BE11D52FB42FBF2E772FB773ACF96469493BECCCFF44D24700145DBD324D138C92B04FE405C233D4DE7B91C325AE727D1BE01D52AF0D03D22E238734714D229DA4C83D2937F5C4F72D19923E3FAFF4E1119DF936886EE1D0CAAF45F032A1D72BEF2CB30C761497200FF3E5196416902035298FE6174E04332397DD565928C35D64D65E03A1E6F67BF6E71D65A4E5B99FFA905558E8F3EE63AF6F908112489D827CABA3E702BA642730C862056EF32F942E95B1B1C7395E2133BD4B3C4357A72FF96B08397EABB719D6D3D7C92F747D48C490EFBB5211A654CEDCA7497360457&sign=B6B1F4260A0D64AAE9E7730793AB2618A988CFEE (Caused by NewConnectionError('<urllib3.connection.HTTPSConnection object at 0x7f180d4dba90>: Failed to establish a new connection: [Errno 101] Network is unreachable'))
### 执行结果
- **登录状态**: 登录失败
- **签到结果**: 

---
## 执行统计
- **结束时间**: 2025-09-06 15:52:25
- **运行时长**: 547.79 秒

✅ **所有账户处理完成！**
