# 天翼云盘签到记录

[![签到状态](https://github.com/xdrive5/cloud9/actions/workflows/main.yml/badge.svg)](https://github.com/xdrive5/cloud9/actions/workflows/main.yml) [![项目主页](https://img.shields.io/badge/GitHub-项目主页-blue?logo=github)](https://github.com/xdrive5/cloud9)

**最后更新:** 2025-08-28 15:43:55 CST

## 快速导航

- 🔄 [查看Action运行记录](https://github.com/xdrive5/cloud9/actions)
- 📋 [查看最新运行](https://github.com/xdrive5/cloud9/actions/runs/17289292426)
- 🏠 [返回项目主页](https://github.com/xdrive5/cloud9)
- ⚙️ [手动触发签到](https://github.com/xdrive5/cloud9/actions/workflows/main.yml)

## 签到详情

# 天翼云盘自动签到抽奖程序

## 执行概览
- **启动时间**: 2025-08-28 15:43:55
- **账户数量**: 2 个

## 账户1
登录过程出错: HTTPSConnectionPool(host='open.e.189.cn', port=443): Max retries exceeded with url: /api/logbox/oauth2/autoLogin.do?appId=cloud&version=v1.1&clientType=20010&format=redirect&paras=1F42946EB49B704335FD09DA6C86E5D4A99CDA0618743C7DB4B3BBAE5FE11F318FA13EC7A61FDC89B082E5F583BDF9FD602B2C8B2058069729AC5CB95D8D5C94F6F97C1A878B649CA2A701ABF9B26970886AED23871F1E9981BC93D0E736E6FEEDB88A4445CB86024D9A83C3146C60196DAD57B66FC6EA5D92FBE0DE55B0E64292102844C831032E1BBCF803903D99175627F5FB8881E971B3BE4CACF02D448E39CA62596A0E12D1DACEDB6D1DAF931283D23C6F617894B7C0891823E252ECFCA30513016E5BA157D61B1F5801A290875D473C5DFEAA4177C9B2786BAE5362D23BBC0CA2EB8DCF5D1346A5FEE486F396B7FAB7511BC72E7D13DB5670DD00B503160DE47AFD901B5A858AF9B788541941911A4F6B0C6F113D0225DEF36DE714E3DC522FE87B3F85501C9F4C3D0C8A98D05DC522B77EC515166BA97E280392DCD074913B6B738B806F7F012F95CB867B447069A517ECA0F54CE0535C45656B06BFA0019972D1864BE8657AD55BE185E584A28B36751BF482D1A35E56F9E4321466CD6F29771695EC7F4F4A74DD418A2824A506D64204E4210289B4257536019D6C133FBE59F474F2FEFEF98B0E8CCCDC27493BE7383AB021D631FF7EEC1D0B53496B9C0E53250C5251FA9CF7BDC00AC0DF268F25E049A53D37A7EA83AE9DBC44231D9691859AE55745C1D6D2815DA86B62969E3E18F03D90FD3ABCCB9DD58DBA8BB0F668BF8073F11F621922BF92350099223730C52862CB52&sign=85CC89CCD988A0F5D9E02537EB426ED1281D412A (Caused by NewConnectionError('<urllib3.connection.HTTPSConnection object at 0x7f5e7390ca90>: Failed to establish a new connection: [Errno 101] Network is unreachable'))
### 执行结果
- **登录状态**: 登录失败
- **签到结果**: 

## 账户2
登录过程出错: HTTPSConnectionPool(host='open.e.189.cn', port=443): Max retries exceeded with url: /api/logbox/oauth2/autoLogin.do?appId=cloud&version=v1.1&clientType=20010&format=redirect&paras=DAE45808ABAD7675D13303342D6F9CD4D7CB6E82E75D2D5C8A772A038CC85A8FDB67252DA592E68510E0F41FD65733DD89C53F28A692E7142DB4E38779007B93AE8FF72C1956DE717DB1740CF1FEC7A0F1920F1E511310D1FDC7ECA370764D12500B5BAE30D88ECDC35108F8039F51DC082446A084BE57E4B89BAF3AEBB987929581F744B43D85C2C316ECAEFA6D38EFA2ED85CC7E8215A9489D5C2213E64E4758F1FCE6A2C0ACE68611C75AC1711887926DFBF4CC2720DD1083B16BE8F3C9D15EF0BB57DA4B454284BBCA09DA9AA6A6C73445D9CCEB6AAA5882E3658B38F4FB4BF097C319B1AB3F6706213AEAB8056945029D90763A651260060427FC1B696A824A9367C38649AF304DD4BE5A4AEF0BA0328D017638C3E69560B98BB8B7C30DB7B76BE6B4172E747BD61489F86F4C387D79D0561F394C213DB91055ABA59A3701BFC219ED7AEA3920083AF2926139924CE6AE311784771FFD808467BB01A900939AEF46CDCFA3791CCB09D0D9F0930F75D4B42F096DC08084C6262AF2B59CF1530ABDEDFE6EFF055527CE2C7D5A35A682939BA79502E3C89FA4D87CAB99B4ED20FF07BC1954D67B7C16CD7EBF5312E3AD8FD03F303B792E8F5453902CC4CFD7FAC0D5AC5AB31B7478B047DBA3277B37E78520411942C0D18BC50847189587F09B93D622D654B3CC6D5262B9E0F37F1E316F43C5E25D81F7A1AE391EC44D1493CD0B8A919012E4EDD25B2EC2310B5EE31CAD761F5D236CD6&sign=702F3B762D93E783460191E65245616589550E5A (Caused by NewConnectionError('<urllib3.connection.HTTPSConnection object at 0x7f5e739141d0>: Failed to establish a new connection: [Errno 101] Network is unreachable'))
### 执行结果
- **登录状态**: 登录失败
- **签到结果**: 

---
## 执行统计
- **结束时间**: 2025-08-28 15:52:56
- **运行时长**: 540.65 秒

✅ **所有账户处理完成！**
