# 天翼云盘签到记录

[![签到状态](https://github.com/xdrive5/cloud9/actions/workflows/main.yml/badge.svg)](https://github.com/xdrive5/cloud9/actions/workflows/main.yml) [![项目主页](https://img.shields.io/badge/GitHub-项目主页-blue?logo=github)](https://github.com/xdrive5/cloud9)

**最后更新:** 2025-09-19 15:29:29 CST

## 快速导航

- 🔄 [查看Action运行记录](https://github.com/xdrive5/cloud9/actions)
- 📋 [查看最新运行](https://github.com/xdrive5/cloud9/actions/runs/17851672105)
- 🏠 [返回项目主页](https://github.com/xdrive5/cloud9)
- ⚙️ [手动触发签到](https://github.com/xdrive5/cloud9/actions/workflows/main.yml)

## 签到详情

# 天翼云盘自动签到抽奖程序

## 执行概览
- **启动时间**: 2025-09-19 15:29:29
- **账户数量**: 2 个

## 账户1
登录过程出错: HTTPSConnectionPool(host='open.e.189.cn', port=443): Max retries exceeded with url: /api/logbox/oauth2/autoLogin.do?appId=cloud&version=v1.1&clientType=20010&format=redirect&paras=FB5561DC5601D89E05A8C1A113F59238B39C5A8F016055183052D7186EC13808436F55A84FF811B3A07B6779A40BA2C6EE5EA6B181D2CB5ED4BD1DE5BCAFAA8EF110352141D64345D059E09632CBB8B984CD665A9C9E9F4891A4256E13A915E1A6B60160415EE1D247BA0839BD41CAACF5DBB5833DA25C63E00C7BAED4C48231AA9409E459B765ECC25F58BA5B9DC15B038A673AC5018FB8D4EADDCFBC6C5C1716CE17C5318C58368A310EB3D9653E5A18E55827A9B2DC72B52E157CC41F6ACE1FE63AB731E30933AEBC8AE720A9685D310D54D7F0BD605AA413AA7B8FAADB6DDC9420BDEE1C708D869F18121E87794ED05628A26FDCDB0F57070169406A47EB6A92B2F618F5BF42774C70173A782D30839CAEBF628D424C8BD3C3F1C146EB897907B1ED7F3F47674DEC1EB202994CA2D0CE0F3FB8905D5EA2414521AEDFE8CCB3990EBF5C40B9ED7ACD4A6E9F1EDA05DB98F2780BB27ED4EC47CC507E6FCF18EBCFD69C23AE0C3FC8549BAEF2C392FE2136B2574E84373B51473B42B37D82B6DBD4787F45C44EC77D1787860FFCBD94ACE647D51EA1AE9D7389AD92F9B4164B461D7D4E2B4C45ADB663A90C6C85EE2764AF62DEB22C52527635B27B12EF128FBD5B38C6CD2A36BE423EF8B9A3F1893345F2C3FAC610B2E89FD174B9AB773B9A9486BD7157D403CC57C46707B99ABB1C930149BF910F31F7068ED609C85DD192B777DDBC6921CF358401F00E73AC42FC7ECFFD49365ECA8B&sign=DF00870E5E0B03ECA308E0026D885E1761A3F8D6 (Caused by NewConnectionError('<urllib3.connection.HTTPSConnection object at 0x7f832b3b4490>: Failed to establish a new connection: [Errno 101] Network is unreachable'))
### 执行结果
- **登录状态**: 登录失败
- **签到结果**: 

## 账户2
登录过程出错: HTTPSConnectionPool(host='open.e.189.cn', port=443): Max retries exceeded with url: /api/logbox/oauth2/autoLogin.do?appId=cloud&version=v1.1&clientType=20010&format=redirect&paras=55A2CF6C58666E6A6F71816675647A95587DDE8B1B4FD551598406F8CC4584BDCD518217785E02A6FDEE91C39617053AA57491FAB06708E5F76D5485B62B8ED251F6BF1F6E62BBF602E1CDCCDBE6B8E5F4D31EF9263B751FDDFC7202B1DD24407805E69CC3896F2233D49ED753F3A9F5563CC96CD2FFE1DB13B4635D6404EA98DFB9D3D6640C12A7E7DBD9C4489B161C20430A478F9FB8ECC5DF5736B3342D3473CFEC91785A02EF43183CBD892896AF9E8F52A33F5F8C045529FFFD9ECBB37034A0EF8C2E9A10BA490DF140DB7C08848FCAB6AE0735F2E4BF5816997C281F29F936C3579825D5C4DFA90BD6FAED8EC9C1586E43164299C1D7E0D4A41BA9CE75EAB3FDA46B838254EBE9ABC7A51FEEAC5AAECB78F03A460436E2FAA0E2906BFF77FF848D651F1D30389A63A961B9AF2A6FA747C8E15CDB84A797C95E4FF542444595EE0884FA24F734D4D901EE19E2CD0F4E61305A29474E96DB40961BEE48128475E240CBCC6CF98D5D2A9CDA3D43BEAAFC5DC55F0476D0B3C58E96E96240C76426DB41567B7201B90031AD80E0CC55CF99890A5FB51C980B47EE0B72B5D0B63F89C825CC20D1E1F481E03443CEA7015B51E23C07FADAD9B8521D6E9A80E1D99299601955D5F2D86269B126625A2B49B9C907FBD077E298D4C50E3A19E3F78F662BF4DF4DCD4D68616C2B3BCF698EB941BE19F8E890C0069102E6C6C27B6CE16566F24295619D5358A6E684BEFA5EB30D46B92DAB347337&sign=086BA612F753DC521ABD1BD61DEC90226ABD18BE (Caused by NewConnectionError('<urllib3.connection.HTTPSConnection object at 0x7f832b3b7b90>: Failed to establish a new connection: [Errno 101] Network is unreachable'))
### 执行结果
- **登录状态**: 登录失败
- **签到结果**: 

---
## 执行统计
- **结束时间**: 2025-09-19 15:38:32
- **运行时长**: 543.03 秒

✅ **所有账户处理完成！**
